{
 "cells": [
  {
   "cell_type": "code",
   "execution_count": 1,
   "metadata": {},
   "outputs": [
    {
     "name": "stdout",
     "output_type": "stream",
     "text": [
      "Fitting 3 folds for each of 36 candidates, totalling 108 fits\n"
     ]
    },
    {
     "name": "stderr",
     "output_type": "stream",
     "text": [
      "/var/folders/8z/bf26sjgx09qcs_63cnr3hp880000gn/T/ipykernel_35102/2150697309.py:85: DeprecationWarning: KerasClassifier is deprecated, use Sci-Keras (https://github.com/adriangb/scikeras) instead. See https://www.adriangb.com/scikeras/stable/migration.html for help migrating.\n",
      "  model = KerasClassifier(build_fn=build_gru_model, input_shape=(X_train.shape[1],))\n",
      "2024-10-17 12:42:37.540973: I tensorflow/core/platform/cpu_feature_guard.cc:193] This TensorFlow binary is optimized with oneAPI Deep Neural Network Library (oneDNN) to use the following CPU instructions in performance-critical operations:  AVX2 FMA\n",
      "To enable them in other operations, rebuild TensorFlow with the appropriate compiler flags.\n",
      "2024-10-17 12:42:37.541622: I tensorflow/core/platform/cpu_feature_guard.cc:193] This TensorFlow binary is optimized with oneAPI Deep Neural Network Library (oneDNN) to use the following CPU instructions in performance-critical operations:  AVX2 FMA\n",
      "To enable them in other operations, rebuild TensorFlow with the appropriate compiler flags.\n",
      "2024-10-17 12:42:37.542537: I tensorflow/core/platform/cpu_feature_guard.cc:193] This TensorFlow binary is optimized with oneAPI Deep Neural Network Library (oneDNN) to use the following CPU instructions in performance-critical operations:  AVX2 FMA\n",
      "To enable them in other operations, rebuild TensorFlow with the appropriate compiler flags.\n",
      "2024-10-17 12:42:37.547358: I tensorflow/core/platform/cpu_feature_guard.cc:193] This TensorFlow binary is optimized with oneAPI Deep Neural Network Library (oneDNN) to use the following CPU instructions in performance-critical operations:  AVX2 FMA\n",
      "To enable them in other operations, rebuild TensorFlow with the appropriate compiler flags.\n",
      "/Users/ahmedabd/miniconda3/envs/my_jupyter_env/lib/python3.9/site-packages/sklearn/model_selection/_validation.py:372: FitFailedWarning: \n",
      "108 fits failed out of a total of 108.\n",
      "The score on these train-test partitions for these parameters will be set to nan.\n",
      "If these failures are not expected, you can try to debug them by setting error_score='raise'.\n",
      "\n",
      "Below are more details about the failures:\n",
      "--------------------------------------------------------------------------------\n",
      "4 fits failed with the following error:\n",
      "Traceback (most recent call last):\n",
      "  File \"/Users/ahmedabd/miniconda3/envs/my_jupyter_env/lib/python3.9/site-packages/sklearn/model_selection/_validation.py\", line 680, in _fit_and_score\n",
      "    estimator.fit(X_train, y_train, **fit_params)\n",
      "  File \"/Users/ahmedabd/miniconda3/envs/my_jupyter_env/lib/python3.9/site-packages/keras/wrappers/scikit_learn.py\", line 236, in fit\n",
      "    return super(KerasClassifier, self).fit(x, y, **kwargs)\n",
      "  File \"/Users/ahmedabd/miniconda3/envs/my_jupyter_env/lib/python3.9/site-packages/keras/wrappers/scikit_learn.py\", line 155, in fit\n",
      "    self.model = self.build_fn(**self.filter_sk_params(self.build_fn))\n",
      "  File \"/var/folders/8z/bf26sjgx09qcs_63cnr3hp880000gn/T/ipykernel_35102/2150697309.py\", line 72, in build_gru_model\n",
      "  File \"/Users/ahmedabd/miniconda3/envs/my_jupyter_env/lib/python3.9/site-packages/tensorflow/python/training/tracking/base.py\", line 587, in _method_wrapper\n",
      "    result = method(self, *args, **kwargs)\n",
      "  File \"/Users/ahmedabd/miniconda3/envs/my_jupyter_env/lib/python3.9/site-packages/keras/utils/traceback_utils.py\", line 67, in error_handler\n",
      "    raise e.with_traceback(filtered_tb) from None\n",
      "  File \"/Users/ahmedabd/miniconda3/envs/my_jupyter_env/lib/python3.9/site-packages/keras/engine/input_spec.py\", line 214, in assert_input_compatibility\n",
      "    raise ValueError(f'Input {input_index} of layer \"{layer_name}\" '\n",
      "ValueError: Input 0 of layer \"gru\" is incompatible with the layer: expected ndim=3, found ndim=2. Full shape received: (None, 6)\n",
      "\n",
      "--------------------------------------------------------------------------------\n",
      "4 fits failed with the following error:\n",
      "Traceback (most recent call last):\n",
      "  File \"/Users/ahmedabd/miniconda3/envs/my_jupyter_env/lib/python3.9/site-packages/sklearn/model_selection/_validation.py\", line 680, in _fit_and_score\n",
      "    estimator.fit(X_train, y_train, **fit_params)\n",
      "  File \"/Users/ahmedabd/miniconda3/envs/my_jupyter_env/lib/python3.9/site-packages/keras/wrappers/scikit_learn.py\", line 236, in fit\n",
      "    return super(KerasClassifier, self).fit(x, y, **kwargs)\n",
      "  File \"/Users/ahmedabd/miniconda3/envs/my_jupyter_env/lib/python3.9/site-packages/keras/wrappers/scikit_learn.py\", line 155, in fit\n",
      "    self.model = self.build_fn(**self.filter_sk_params(self.build_fn))\n",
      "  File \"/var/folders/8z/bf26sjgx09qcs_63cnr3hp880000gn/T/ipykernel_35102/2150697309.py\", line 72, in build_gru_model\n",
      "  File \"/Users/ahmedabd/miniconda3/envs/my_jupyter_env/lib/python3.9/site-packages/tensorflow/python/training/tracking/base.py\", line 587, in _method_wrapper\n",
      "    result = method(self, *args, **kwargs)\n",
      "  File \"/Users/ahmedabd/miniconda3/envs/my_jupyter_env/lib/python3.9/site-packages/keras/utils/traceback_utils.py\", line 67, in error_handler\n",
      "    raise e.with_traceback(filtered_tb) from None\n",
      "  File \"/Users/ahmedabd/miniconda3/envs/my_jupyter_env/lib/python3.9/site-packages/keras/engine/input_spec.py\", line 214, in assert_input_compatibility\n",
      "    raise ValueError(f'Input {input_index} of layer \"{layer_name}\" '\n",
      "ValueError: Input 0 of layer \"gru_1\" is incompatible with the layer: expected ndim=3, found ndim=2. Full shape received: (None, 6)\n",
      "\n",
      "--------------------------------------------------------------------------------\n",
      "4 fits failed with the following error:\n",
      "Traceback (most recent call last):\n",
      "  File \"/Users/ahmedabd/miniconda3/envs/my_jupyter_env/lib/python3.9/site-packages/sklearn/model_selection/_validation.py\", line 680, in _fit_and_score\n",
      "    estimator.fit(X_train, y_train, **fit_params)\n",
      "  File \"/Users/ahmedabd/miniconda3/envs/my_jupyter_env/lib/python3.9/site-packages/keras/wrappers/scikit_learn.py\", line 236, in fit\n",
      "    return super(KerasClassifier, self).fit(x, y, **kwargs)\n",
      "  File \"/Users/ahmedabd/miniconda3/envs/my_jupyter_env/lib/python3.9/site-packages/keras/wrappers/scikit_learn.py\", line 155, in fit\n",
      "    self.model = self.build_fn(**self.filter_sk_params(self.build_fn))\n",
      "  File \"/var/folders/8z/bf26sjgx09qcs_63cnr3hp880000gn/T/ipykernel_35102/2150697309.py\", line 72, in build_gru_model\n",
      "  File \"/Users/ahmedabd/miniconda3/envs/my_jupyter_env/lib/python3.9/site-packages/tensorflow/python/training/tracking/base.py\", line 587, in _method_wrapper\n",
      "    result = method(self, *args, **kwargs)\n",
      "  File \"/Users/ahmedabd/miniconda3/envs/my_jupyter_env/lib/python3.9/site-packages/keras/utils/traceback_utils.py\", line 67, in error_handler\n",
      "    raise e.with_traceback(filtered_tb) from None\n",
      "  File \"/Users/ahmedabd/miniconda3/envs/my_jupyter_env/lib/python3.9/site-packages/keras/engine/input_spec.py\", line 214, in assert_input_compatibility\n",
      "    raise ValueError(f'Input {input_index} of layer \"{layer_name}\" '\n",
      "ValueError: Input 0 of layer \"gru_2\" is incompatible with the layer: expected ndim=3, found ndim=2. Full shape received: (None, 6)\n",
      "\n",
      "--------------------------------------------------------------------------------\n",
      "4 fits failed with the following error:\n",
      "Traceback (most recent call last):\n",
      "  File \"/Users/ahmedabd/miniconda3/envs/my_jupyter_env/lib/python3.9/site-packages/sklearn/model_selection/_validation.py\", line 680, in _fit_and_score\n",
      "    estimator.fit(X_train, y_train, **fit_params)\n",
      "  File \"/Users/ahmedabd/miniconda3/envs/my_jupyter_env/lib/python3.9/site-packages/keras/wrappers/scikit_learn.py\", line 236, in fit\n",
      "    return super(KerasClassifier, self).fit(x, y, **kwargs)\n",
      "  File \"/Users/ahmedabd/miniconda3/envs/my_jupyter_env/lib/python3.9/site-packages/keras/wrappers/scikit_learn.py\", line 155, in fit\n",
      "    self.model = self.build_fn(**self.filter_sk_params(self.build_fn))\n",
      "  File \"/var/folders/8z/bf26sjgx09qcs_63cnr3hp880000gn/T/ipykernel_35102/2150697309.py\", line 72, in build_gru_model\n",
      "  File \"/Users/ahmedabd/miniconda3/envs/my_jupyter_env/lib/python3.9/site-packages/tensorflow/python/training/tracking/base.py\", line 587, in _method_wrapper\n",
      "    result = method(self, *args, **kwargs)\n",
      "  File \"/Users/ahmedabd/miniconda3/envs/my_jupyter_env/lib/python3.9/site-packages/keras/utils/traceback_utils.py\", line 67, in error_handler\n",
      "    raise e.with_traceback(filtered_tb) from None\n",
      "  File \"/Users/ahmedabd/miniconda3/envs/my_jupyter_env/lib/python3.9/site-packages/keras/engine/input_spec.py\", line 214, in assert_input_compatibility\n",
      "    raise ValueError(f'Input {input_index} of layer \"{layer_name}\" '\n",
      "ValueError: Input 0 of layer \"gru_3\" is incompatible with the layer: expected ndim=3, found ndim=2. Full shape received: (None, 6)\n",
      "\n",
      "--------------------------------------------------------------------------------\n",
      "4 fits failed with the following error:\n",
      "Traceback (most recent call last):\n",
      "  File \"/Users/ahmedabd/miniconda3/envs/my_jupyter_env/lib/python3.9/site-packages/sklearn/model_selection/_validation.py\", line 680, in _fit_and_score\n",
      "    estimator.fit(X_train, y_train, **fit_params)\n",
      "  File \"/Users/ahmedabd/miniconda3/envs/my_jupyter_env/lib/python3.9/site-packages/keras/wrappers/scikit_learn.py\", line 236, in fit\n",
      "    return super(KerasClassifier, self).fit(x, y, **kwargs)\n",
      "  File \"/Users/ahmedabd/miniconda3/envs/my_jupyter_env/lib/python3.9/site-packages/keras/wrappers/scikit_learn.py\", line 155, in fit\n",
      "    self.model = self.build_fn(**self.filter_sk_params(self.build_fn))\n",
      "  File \"/var/folders/8z/bf26sjgx09qcs_63cnr3hp880000gn/T/ipykernel_35102/2150697309.py\", line 72, in build_gru_model\n",
      "  File \"/Users/ahmedabd/miniconda3/envs/my_jupyter_env/lib/python3.9/site-packages/tensorflow/python/training/tracking/base.py\", line 587, in _method_wrapper\n",
      "    result = method(self, *args, **kwargs)\n",
      "  File \"/Users/ahmedabd/miniconda3/envs/my_jupyter_env/lib/python3.9/site-packages/keras/utils/traceback_utils.py\", line 67, in error_handler\n",
      "    raise e.with_traceback(filtered_tb) from None\n",
      "  File \"/Users/ahmedabd/miniconda3/envs/my_jupyter_env/lib/python3.9/site-packages/keras/engine/input_spec.py\", line 214, in assert_input_compatibility\n",
      "    raise ValueError(f'Input {input_index} of layer \"{layer_name}\" '\n",
      "ValueError: Input 0 of layer \"gru_4\" is incompatible with the layer: expected ndim=3, found ndim=2. Full shape received: (None, 6)\n",
      "\n",
      "--------------------------------------------------------------------------------\n",
      "4 fits failed with the following error:\n",
      "Traceback (most recent call last):\n",
      "  File \"/Users/ahmedabd/miniconda3/envs/my_jupyter_env/lib/python3.9/site-packages/sklearn/model_selection/_validation.py\", line 680, in _fit_and_score\n",
      "    estimator.fit(X_train, y_train, **fit_params)\n",
      "  File \"/Users/ahmedabd/miniconda3/envs/my_jupyter_env/lib/python3.9/site-packages/keras/wrappers/scikit_learn.py\", line 236, in fit\n",
      "    return super(KerasClassifier, self).fit(x, y, **kwargs)\n",
      "  File \"/Users/ahmedabd/miniconda3/envs/my_jupyter_env/lib/python3.9/site-packages/keras/wrappers/scikit_learn.py\", line 155, in fit\n",
      "    self.model = self.build_fn(**self.filter_sk_params(self.build_fn))\n",
      "  File \"/var/folders/8z/bf26sjgx09qcs_63cnr3hp880000gn/T/ipykernel_35102/2150697309.py\", line 72, in build_gru_model\n",
      "  File \"/Users/ahmedabd/miniconda3/envs/my_jupyter_env/lib/python3.9/site-packages/tensorflow/python/training/tracking/base.py\", line 587, in _method_wrapper\n",
      "    result = method(self, *args, **kwargs)\n",
      "  File \"/Users/ahmedabd/miniconda3/envs/my_jupyter_env/lib/python3.9/site-packages/keras/utils/traceback_utils.py\", line 67, in error_handler\n",
      "    raise e.with_traceback(filtered_tb) from None\n",
      "  File \"/Users/ahmedabd/miniconda3/envs/my_jupyter_env/lib/python3.9/site-packages/keras/engine/input_spec.py\", line 214, in assert_input_compatibility\n",
      "    raise ValueError(f'Input {input_index} of layer \"{layer_name}\" '\n",
      "ValueError: Input 0 of layer \"gru_5\" is incompatible with the layer: expected ndim=3, found ndim=2. Full shape received: (None, 6)\n",
      "\n",
      "--------------------------------------------------------------------------------\n",
      "4 fits failed with the following error:\n",
      "Traceback (most recent call last):\n",
      "  File \"/Users/ahmedabd/miniconda3/envs/my_jupyter_env/lib/python3.9/site-packages/sklearn/model_selection/_validation.py\", line 680, in _fit_and_score\n",
      "    estimator.fit(X_train, y_train, **fit_params)\n",
      "  File \"/Users/ahmedabd/miniconda3/envs/my_jupyter_env/lib/python3.9/site-packages/keras/wrappers/scikit_learn.py\", line 236, in fit\n",
      "    return super(KerasClassifier, self).fit(x, y, **kwargs)\n",
      "  File \"/Users/ahmedabd/miniconda3/envs/my_jupyter_env/lib/python3.9/site-packages/keras/wrappers/scikit_learn.py\", line 155, in fit\n",
      "    self.model = self.build_fn(**self.filter_sk_params(self.build_fn))\n",
      "  File \"/var/folders/8z/bf26sjgx09qcs_63cnr3hp880000gn/T/ipykernel_35102/2150697309.py\", line 72, in build_gru_model\n",
      "  File \"/Users/ahmedabd/miniconda3/envs/my_jupyter_env/lib/python3.9/site-packages/tensorflow/python/training/tracking/base.py\", line 587, in _method_wrapper\n",
      "    result = method(self, *args, **kwargs)\n",
      "  File \"/Users/ahmedabd/miniconda3/envs/my_jupyter_env/lib/python3.9/site-packages/keras/utils/traceback_utils.py\", line 67, in error_handler\n",
      "    raise e.with_traceback(filtered_tb) from None\n",
      "  File \"/Users/ahmedabd/miniconda3/envs/my_jupyter_env/lib/python3.9/site-packages/keras/engine/input_spec.py\", line 214, in assert_input_compatibility\n",
      "    raise ValueError(f'Input {input_index} of layer \"{layer_name}\" '\n",
      "ValueError: Input 0 of layer \"gru_6\" is incompatible with the layer: expected ndim=3, found ndim=2. Full shape received: (None, 6)\n",
      "\n",
      "--------------------------------------------------------------------------------\n",
      "4 fits failed with the following error:\n",
      "Traceback (most recent call last):\n",
      "  File \"/Users/ahmedabd/miniconda3/envs/my_jupyter_env/lib/python3.9/site-packages/sklearn/model_selection/_validation.py\", line 680, in _fit_and_score\n",
      "    estimator.fit(X_train, y_train, **fit_params)\n",
      "  File \"/Users/ahmedabd/miniconda3/envs/my_jupyter_env/lib/python3.9/site-packages/keras/wrappers/scikit_learn.py\", line 236, in fit\n",
      "    return super(KerasClassifier, self).fit(x, y, **kwargs)\n",
      "  File \"/Users/ahmedabd/miniconda3/envs/my_jupyter_env/lib/python3.9/site-packages/keras/wrappers/scikit_learn.py\", line 155, in fit\n",
      "    self.model = self.build_fn(**self.filter_sk_params(self.build_fn))\n",
      "  File \"/var/folders/8z/bf26sjgx09qcs_63cnr3hp880000gn/T/ipykernel_35102/2150697309.py\", line 72, in build_gru_model\n",
      "  File \"/Users/ahmedabd/miniconda3/envs/my_jupyter_env/lib/python3.9/site-packages/tensorflow/python/training/tracking/base.py\", line 587, in _method_wrapper\n",
      "    result = method(self, *args, **kwargs)\n",
      "  File \"/Users/ahmedabd/miniconda3/envs/my_jupyter_env/lib/python3.9/site-packages/keras/utils/traceback_utils.py\", line 67, in error_handler\n",
      "    raise e.with_traceback(filtered_tb) from None\n",
      "  File \"/Users/ahmedabd/miniconda3/envs/my_jupyter_env/lib/python3.9/site-packages/keras/engine/input_spec.py\", line 214, in assert_input_compatibility\n",
      "    raise ValueError(f'Input {input_index} of layer \"{layer_name}\" '\n",
      "ValueError: Input 0 of layer \"gru_7\" is incompatible with the layer: expected ndim=3, found ndim=2. Full shape received: (None, 6)\n",
      "\n",
      "--------------------------------------------------------------------------------\n",
      "4 fits failed with the following error:\n",
      "Traceback (most recent call last):\n",
      "  File \"/Users/ahmedabd/miniconda3/envs/my_jupyter_env/lib/python3.9/site-packages/sklearn/model_selection/_validation.py\", line 680, in _fit_and_score\n",
      "    estimator.fit(X_train, y_train, **fit_params)\n",
      "  File \"/Users/ahmedabd/miniconda3/envs/my_jupyter_env/lib/python3.9/site-packages/keras/wrappers/scikit_learn.py\", line 236, in fit\n",
      "    return super(KerasClassifier, self).fit(x, y, **kwargs)\n",
      "  File \"/Users/ahmedabd/miniconda3/envs/my_jupyter_env/lib/python3.9/site-packages/keras/wrappers/scikit_learn.py\", line 155, in fit\n",
      "    self.model = self.build_fn(**self.filter_sk_params(self.build_fn))\n",
      "  File \"/var/folders/8z/bf26sjgx09qcs_63cnr3hp880000gn/T/ipykernel_35102/2150697309.py\", line 72, in build_gru_model\n",
      "  File \"/Users/ahmedabd/miniconda3/envs/my_jupyter_env/lib/python3.9/site-packages/tensorflow/python/training/tracking/base.py\", line 587, in _method_wrapper\n",
      "    result = method(self, *args, **kwargs)\n",
      "  File \"/Users/ahmedabd/miniconda3/envs/my_jupyter_env/lib/python3.9/site-packages/keras/utils/traceback_utils.py\", line 67, in error_handler\n",
      "    raise e.with_traceback(filtered_tb) from None\n",
      "  File \"/Users/ahmedabd/miniconda3/envs/my_jupyter_env/lib/python3.9/site-packages/keras/engine/input_spec.py\", line 214, in assert_input_compatibility\n",
      "    raise ValueError(f'Input {input_index} of layer \"{layer_name}\" '\n",
      "ValueError: Input 0 of layer \"gru_8\" is incompatible with the layer: expected ndim=3, found ndim=2. Full shape received: (None, 6)\n",
      "\n",
      "--------------------------------------------------------------------------------\n",
      "4 fits failed with the following error:\n",
      "Traceback (most recent call last):\n",
      "  File \"/Users/ahmedabd/miniconda3/envs/my_jupyter_env/lib/python3.9/site-packages/sklearn/model_selection/_validation.py\", line 680, in _fit_and_score\n",
      "    estimator.fit(X_train, y_train, **fit_params)\n",
      "  File \"/Users/ahmedabd/miniconda3/envs/my_jupyter_env/lib/python3.9/site-packages/keras/wrappers/scikit_learn.py\", line 236, in fit\n",
      "    return super(KerasClassifier, self).fit(x, y, **kwargs)\n",
      "  File \"/Users/ahmedabd/miniconda3/envs/my_jupyter_env/lib/python3.9/site-packages/keras/wrappers/scikit_learn.py\", line 155, in fit\n",
      "    self.model = self.build_fn(**self.filter_sk_params(self.build_fn))\n",
      "  File \"/var/folders/8z/bf26sjgx09qcs_63cnr3hp880000gn/T/ipykernel_35102/2150697309.py\", line 72, in build_gru_model\n",
      "  File \"/Users/ahmedabd/miniconda3/envs/my_jupyter_env/lib/python3.9/site-packages/tensorflow/python/training/tracking/base.py\", line 587, in _method_wrapper\n",
      "    result = method(self, *args, **kwargs)\n",
      "  File \"/Users/ahmedabd/miniconda3/envs/my_jupyter_env/lib/python3.9/site-packages/keras/utils/traceback_utils.py\", line 67, in error_handler\n",
      "    raise e.with_traceback(filtered_tb) from None\n",
      "  File \"/Users/ahmedabd/miniconda3/envs/my_jupyter_env/lib/python3.9/site-packages/keras/engine/input_spec.py\", line 214, in assert_input_compatibility\n",
      "    raise ValueError(f'Input {input_index} of layer \"{layer_name}\" '\n",
      "ValueError: Input 0 of layer \"gru_9\" is incompatible with the layer: expected ndim=3, found ndim=2. Full shape received: (None, 6)\n",
      "\n",
      "--------------------------------------------------------------------------------\n",
      "4 fits failed with the following error:\n",
      "Traceback (most recent call last):\n",
      "  File \"/Users/ahmedabd/miniconda3/envs/my_jupyter_env/lib/python3.9/site-packages/sklearn/model_selection/_validation.py\", line 680, in _fit_and_score\n",
      "    estimator.fit(X_train, y_train, **fit_params)\n",
      "  File \"/Users/ahmedabd/miniconda3/envs/my_jupyter_env/lib/python3.9/site-packages/keras/wrappers/scikit_learn.py\", line 236, in fit\n",
      "    return super(KerasClassifier, self).fit(x, y, **kwargs)\n",
      "  File \"/Users/ahmedabd/miniconda3/envs/my_jupyter_env/lib/python3.9/site-packages/keras/wrappers/scikit_learn.py\", line 155, in fit\n",
      "    self.model = self.build_fn(**self.filter_sk_params(self.build_fn))\n",
      "  File \"/var/folders/8z/bf26sjgx09qcs_63cnr3hp880000gn/T/ipykernel_35102/2150697309.py\", line 72, in build_gru_model\n",
      "  File \"/Users/ahmedabd/miniconda3/envs/my_jupyter_env/lib/python3.9/site-packages/tensorflow/python/training/tracking/base.py\", line 587, in _method_wrapper\n",
      "    result = method(self, *args, **kwargs)\n",
      "  File \"/Users/ahmedabd/miniconda3/envs/my_jupyter_env/lib/python3.9/site-packages/keras/utils/traceback_utils.py\", line 67, in error_handler\n",
      "    raise e.with_traceback(filtered_tb) from None\n",
      "  File \"/Users/ahmedabd/miniconda3/envs/my_jupyter_env/lib/python3.9/site-packages/keras/engine/input_spec.py\", line 214, in assert_input_compatibility\n",
      "    raise ValueError(f'Input {input_index} of layer \"{layer_name}\" '\n",
      "ValueError: Input 0 of layer \"gru_10\" is incompatible with the layer: expected ndim=3, found ndim=2. Full shape received: (None, 6)\n",
      "\n",
      "--------------------------------------------------------------------------------\n",
      "4 fits failed with the following error:\n",
      "Traceback (most recent call last):\n",
      "  File \"/Users/ahmedabd/miniconda3/envs/my_jupyter_env/lib/python3.9/site-packages/sklearn/model_selection/_validation.py\", line 680, in _fit_and_score\n",
      "    estimator.fit(X_train, y_train, **fit_params)\n",
      "  File \"/Users/ahmedabd/miniconda3/envs/my_jupyter_env/lib/python3.9/site-packages/keras/wrappers/scikit_learn.py\", line 236, in fit\n",
      "    return super(KerasClassifier, self).fit(x, y, **kwargs)\n",
      "  File \"/Users/ahmedabd/miniconda3/envs/my_jupyter_env/lib/python3.9/site-packages/keras/wrappers/scikit_learn.py\", line 155, in fit\n",
      "    self.model = self.build_fn(**self.filter_sk_params(self.build_fn))\n",
      "  File \"/var/folders/8z/bf26sjgx09qcs_63cnr3hp880000gn/T/ipykernel_35102/2150697309.py\", line 72, in build_gru_model\n",
      "  File \"/Users/ahmedabd/miniconda3/envs/my_jupyter_env/lib/python3.9/site-packages/tensorflow/python/training/tracking/base.py\", line 587, in _method_wrapper\n",
      "    result = method(self, *args, **kwargs)\n",
      "  File \"/Users/ahmedabd/miniconda3/envs/my_jupyter_env/lib/python3.9/site-packages/keras/utils/traceback_utils.py\", line 67, in error_handler\n",
      "    raise e.with_traceback(filtered_tb) from None\n",
      "  File \"/Users/ahmedabd/miniconda3/envs/my_jupyter_env/lib/python3.9/site-packages/keras/engine/input_spec.py\", line 214, in assert_input_compatibility\n",
      "    raise ValueError(f'Input {input_index} of layer \"{layer_name}\" '\n",
      "ValueError: Input 0 of layer \"gru_11\" is incompatible with the layer: expected ndim=3, found ndim=2. Full shape received: (None, 6)\n",
      "\n",
      "--------------------------------------------------------------------------------\n",
      "4 fits failed with the following error:\n",
      "Traceback (most recent call last):\n",
      "  File \"/Users/ahmedabd/miniconda3/envs/my_jupyter_env/lib/python3.9/site-packages/sklearn/model_selection/_validation.py\", line 680, in _fit_and_score\n",
      "    estimator.fit(X_train, y_train, **fit_params)\n",
      "  File \"/Users/ahmedabd/miniconda3/envs/my_jupyter_env/lib/python3.9/site-packages/keras/wrappers/scikit_learn.py\", line 236, in fit\n",
      "    return super(KerasClassifier, self).fit(x, y, **kwargs)\n",
      "  File \"/Users/ahmedabd/miniconda3/envs/my_jupyter_env/lib/python3.9/site-packages/keras/wrappers/scikit_learn.py\", line 155, in fit\n",
      "    self.model = self.build_fn(**self.filter_sk_params(self.build_fn))\n",
      "  File \"/var/folders/8z/bf26sjgx09qcs_63cnr3hp880000gn/T/ipykernel_35102/2150697309.py\", line 72, in build_gru_model\n",
      "  File \"/Users/ahmedabd/miniconda3/envs/my_jupyter_env/lib/python3.9/site-packages/tensorflow/python/training/tracking/base.py\", line 587, in _method_wrapper\n",
      "    result = method(self, *args, **kwargs)\n",
      "  File \"/Users/ahmedabd/miniconda3/envs/my_jupyter_env/lib/python3.9/site-packages/keras/utils/traceback_utils.py\", line 67, in error_handler\n",
      "    raise e.with_traceback(filtered_tb) from None\n",
      "  File \"/Users/ahmedabd/miniconda3/envs/my_jupyter_env/lib/python3.9/site-packages/keras/engine/input_spec.py\", line 214, in assert_input_compatibility\n",
      "    raise ValueError(f'Input {input_index} of layer \"{layer_name}\" '\n",
      "ValueError: Input 0 of layer \"gru_12\" is incompatible with the layer: expected ndim=3, found ndim=2. Full shape received: (None, 6)\n",
      "\n",
      "--------------------------------------------------------------------------------\n",
      "4 fits failed with the following error:\n",
      "Traceback (most recent call last):\n",
      "  File \"/Users/ahmedabd/miniconda3/envs/my_jupyter_env/lib/python3.9/site-packages/sklearn/model_selection/_validation.py\", line 680, in _fit_and_score\n",
      "    estimator.fit(X_train, y_train, **fit_params)\n",
      "  File \"/Users/ahmedabd/miniconda3/envs/my_jupyter_env/lib/python3.9/site-packages/keras/wrappers/scikit_learn.py\", line 236, in fit\n",
      "    return super(KerasClassifier, self).fit(x, y, **kwargs)\n",
      "  File \"/Users/ahmedabd/miniconda3/envs/my_jupyter_env/lib/python3.9/site-packages/keras/wrappers/scikit_learn.py\", line 155, in fit\n",
      "    self.model = self.build_fn(**self.filter_sk_params(self.build_fn))\n",
      "  File \"/var/folders/8z/bf26sjgx09qcs_63cnr3hp880000gn/T/ipykernel_35102/2150697309.py\", line 72, in build_gru_model\n",
      "  File \"/Users/ahmedabd/miniconda3/envs/my_jupyter_env/lib/python3.9/site-packages/tensorflow/python/training/tracking/base.py\", line 587, in _method_wrapper\n",
      "    result = method(self, *args, **kwargs)\n",
      "  File \"/Users/ahmedabd/miniconda3/envs/my_jupyter_env/lib/python3.9/site-packages/keras/utils/traceback_utils.py\", line 67, in error_handler\n",
      "    raise e.with_traceback(filtered_tb) from None\n",
      "  File \"/Users/ahmedabd/miniconda3/envs/my_jupyter_env/lib/python3.9/site-packages/keras/engine/input_spec.py\", line 214, in assert_input_compatibility\n",
      "    raise ValueError(f'Input {input_index} of layer \"{layer_name}\" '\n",
      "ValueError: Input 0 of layer \"gru_13\" is incompatible with the layer: expected ndim=3, found ndim=2. Full shape received: (None, 6)\n",
      "\n",
      "--------------------------------------------------------------------------------\n",
      "4 fits failed with the following error:\n",
      "Traceback (most recent call last):\n",
      "  File \"/Users/ahmedabd/miniconda3/envs/my_jupyter_env/lib/python3.9/site-packages/sklearn/model_selection/_validation.py\", line 680, in _fit_and_score\n",
      "    estimator.fit(X_train, y_train, **fit_params)\n",
      "  File \"/Users/ahmedabd/miniconda3/envs/my_jupyter_env/lib/python3.9/site-packages/keras/wrappers/scikit_learn.py\", line 236, in fit\n",
      "    return super(KerasClassifier, self).fit(x, y, **kwargs)\n",
      "  File \"/Users/ahmedabd/miniconda3/envs/my_jupyter_env/lib/python3.9/site-packages/keras/wrappers/scikit_learn.py\", line 155, in fit\n",
      "    self.model = self.build_fn(**self.filter_sk_params(self.build_fn))\n",
      "  File \"/var/folders/8z/bf26sjgx09qcs_63cnr3hp880000gn/T/ipykernel_35102/2150697309.py\", line 72, in build_gru_model\n",
      "  File \"/Users/ahmedabd/miniconda3/envs/my_jupyter_env/lib/python3.9/site-packages/tensorflow/python/training/tracking/base.py\", line 587, in _method_wrapper\n",
      "    result = method(self, *args, **kwargs)\n",
      "  File \"/Users/ahmedabd/miniconda3/envs/my_jupyter_env/lib/python3.9/site-packages/keras/utils/traceback_utils.py\", line 67, in error_handler\n",
      "    raise e.with_traceback(filtered_tb) from None\n",
      "  File \"/Users/ahmedabd/miniconda3/envs/my_jupyter_env/lib/python3.9/site-packages/keras/engine/input_spec.py\", line 214, in assert_input_compatibility\n",
      "    raise ValueError(f'Input {input_index} of layer \"{layer_name}\" '\n",
      "ValueError: Input 0 of layer \"gru_14\" is incompatible with the layer: expected ndim=3, found ndim=2. Full shape received: (None, 6)\n",
      "\n",
      "--------------------------------------------------------------------------------\n",
      "4 fits failed with the following error:\n",
      "Traceback (most recent call last):\n",
      "  File \"/Users/ahmedabd/miniconda3/envs/my_jupyter_env/lib/python3.9/site-packages/sklearn/model_selection/_validation.py\", line 680, in _fit_and_score\n",
      "    estimator.fit(X_train, y_train, **fit_params)\n",
      "  File \"/Users/ahmedabd/miniconda3/envs/my_jupyter_env/lib/python3.9/site-packages/keras/wrappers/scikit_learn.py\", line 236, in fit\n",
      "    return super(KerasClassifier, self).fit(x, y, **kwargs)\n",
      "  File \"/Users/ahmedabd/miniconda3/envs/my_jupyter_env/lib/python3.9/site-packages/keras/wrappers/scikit_learn.py\", line 155, in fit\n",
      "    self.model = self.build_fn(**self.filter_sk_params(self.build_fn))\n",
      "  File \"/var/folders/8z/bf26sjgx09qcs_63cnr3hp880000gn/T/ipykernel_35102/2150697309.py\", line 72, in build_gru_model\n",
      "  File \"/Users/ahmedabd/miniconda3/envs/my_jupyter_env/lib/python3.9/site-packages/tensorflow/python/training/tracking/base.py\", line 587, in _method_wrapper\n",
      "    result = method(self, *args, **kwargs)\n",
      "  File \"/Users/ahmedabd/miniconda3/envs/my_jupyter_env/lib/python3.9/site-packages/keras/utils/traceback_utils.py\", line 67, in error_handler\n",
      "    raise e.with_traceback(filtered_tb) from None\n",
      "  File \"/Users/ahmedabd/miniconda3/envs/my_jupyter_env/lib/python3.9/site-packages/keras/engine/input_spec.py\", line 214, in assert_input_compatibility\n",
      "    raise ValueError(f'Input {input_index} of layer \"{layer_name}\" '\n",
      "ValueError: Input 0 of layer \"gru_15\" is incompatible with the layer: expected ndim=3, found ndim=2. Full shape received: (None, 6)\n",
      "\n",
      "--------------------------------------------------------------------------------\n",
      "4 fits failed with the following error:\n",
      "Traceback (most recent call last):\n",
      "  File \"/Users/ahmedabd/miniconda3/envs/my_jupyter_env/lib/python3.9/site-packages/sklearn/model_selection/_validation.py\", line 680, in _fit_and_score\n",
      "    estimator.fit(X_train, y_train, **fit_params)\n",
      "  File \"/Users/ahmedabd/miniconda3/envs/my_jupyter_env/lib/python3.9/site-packages/keras/wrappers/scikit_learn.py\", line 236, in fit\n",
      "    return super(KerasClassifier, self).fit(x, y, **kwargs)\n",
      "  File \"/Users/ahmedabd/miniconda3/envs/my_jupyter_env/lib/python3.9/site-packages/keras/wrappers/scikit_learn.py\", line 155, in fit\n",
      "    self.model = self.build_fn(**self.filter_sk_params(self.build_fn))\n",
      "  File \"/var/folders/8z/bf26sjgx09qcs_63cnr3hp880000gn/T/ipykernel_35102/2150697309.py\", line 72, in build_gru_model\n",
      "  File \"/Users/ahmedabd/miniconda3/envs/my_jupyter_env/lib/python3.9/site-packages/tensorflow/python/training/tracking/base.py\", line 587, in _method_wrapper\n",
      "    result = method(self, *args, **kwargs)\n",
      "  File \"/Users/ahmedabd/miniconda3/envs/my_jupyter_env/lib/python3.9/site-packages/keras/utils/traceback_utils.py\", line 67, in error_handler\n",
      "    raise e.with_traceback(filtered_tb) from None\n",
      "  File \"/Users/ahmedabd/miniconda3/envs/my_jupyter_env/lib/python3.9/site-packages/keras/engine/input_spec.py\", line 214, in assert_input_compatibility\n",
      "    raise ValueError(f'Input {input_index} of layer \"{layer_name}\" '\n",
      "ValueError: Input 0 of layer \"gru_16\" is incompatible with the layer: expected ndim=3, found ndim=2. Full shape received: (None, 6)\n",
      "\n",
      "--------------------------------------------------------------------------------\n",
      "4 fits failed with the following error:\n",
      "Traceback (most recent call last):\n",
      "  File \"/Users/ahmedabd/miniconda3/envs/my_jupyter_env/lib/python3.9/site-packages/sklearn/model_selection/_validation.py\", line 680, in _fit_and_score\n",
      "    estimator.fit(X_train, y_train, **fit_params)\n",
      "  File \"/Users/ahmedabd/miniconda3/envs/my_jupyter_env/lib/python3.9/site-packages/keras/wrappers/scikit_learn.py\", line 236, in fit\n",
      "    return super(KerasClassifier, self).fit(x, y, **kwargs)\n",
      "  File \"/Users/ahmedabd/miniconda3/envs/my_jupyter_env/lib/python3.9/site-packages/keras/wrappers/scikit_learn.py\", line 155, in fit\n",
      "    self.model = self.build_fn(**self.filter_sk_params(self.build_fn))\n",
      "  File \"/var/folders/8z/bf26sjgx09qcs_63cnr3hp880000gn/T/ipykernel_35102/2150697309.py\", line 72, in build_gru_model\n",
      "  File \"/Users/ahmedabd/miniconda3/envs/my_jupyter_env/lib/python3.9/site-packages/tensorflow/python/training/tracking/base.py\", line 587, in _method_wrapper\n",
      "    result = method(self, *args, **kwargs)\n",
      "  File \"/Users/ahmedabd/miniconda3/envs/my_jupyter_env/lib/python3.9/site-packages/keras/utils/traceback_utils.py\", line 67, in error_handler\n",
      "    raise e.with_traceback(filtered_tb) from None\n",
      "  File \"/Users/ahmedabd/miniconda3/envs/my_jupyter_env/lib/python3.9/site-packages/keras/engine/input_spec.py\", line 214, in assert_input_compatibility\n",
      "    raise ValueError(f'Input {input_index} of layer \"{layer_name}\" '\n",
      "ValueError: Input 0 of layer \"gru_17\" is incompatible with the layer: expected ndim=3, found ndim=2. Full shape received: (None, 6)\n",
      "\n",
      "--------------------------------------------------------------------------------\n",
      "4 fits failed with the following error:\n",
      "Traceback (most recent call last):\n",
      "  File \"/Users/ahmedabd/miniconda3/envs/my_jupyter_env/lib/python3.9/site-packages/sklearn/model_selection/_validation.py\", line 680, in _fit_and_score\n",
      "    estimator.fit(X_train, y_train, **fit_params)\n",
      "  File \"/Users/ahmedabd/miniconda3/envs/my_jupyter_env/lib/python3.9/site-packages/keras/wrappers/scikit_learn.py\", line 236, in fit\n",
      "    return super(KerasClassifier, self).fit(x, y, **kwargs)\n",
      "  File \"/Users/ahmedabd/miniconda3/envs/my_jupyter_env/lib/python3.9/site-packages/keras/wrappers/scikit_learn.py\", line 155, in fit\n",
      "    self.model = self.build_fn(**self.filter_sk_params(self.build_fn))\n",
      "  File \"/var/folders/8z/bf26sjgx09qcs_63cnr3hp880000gn/T/ipykernel_35102/2150697309.py\", line 72, in build_gru_model\n",
      "  File \"/Users/ahmedabd/miniconda3/envs/my_jupyter_env/lib/python3.9/site-packages/tensorflow/python/training/tracking/base.py\", line 587, in _method_wrapper\n",
      "    result = method(self, *args, **kwargs)\n",
      "  File \"/Users/ahmedabd/miniconda3/envs/my_jupyter_env/lib/python3.9/site-packages/keras/utils/traceback_utils.py\", line 67, in error_handler\n",
      "    raise e.with_traceback(filtered_tb) from None\n",
      "  File \"/Users/ahmedabd/miniconda3/envs/my_jupyter_env/lib/python3.9/site-packages/keras/engine/input_spec.py\", line 214, in assert_input_compatibility\n",
      "    raise ValueError(f'Input {input_index} of layer \"{layer_name}\" '\n",
      "ValueError: Input 0 of layer \"gru_18\" is incompatible with the layer: expected ndim=3, found ndim=2. Full shape received: (None, 6)\n",
      "\n",
      "--------------------------------------------------------------------------------\n",
      "4 fits failed with the following error:\n",
      "Traceback (most recent call last):\n",
      "  File \"/Users/ahmedabd/miniconda3/envs/my_jupyter_env/lib/python3.9/site-packages/sklearn/model_selection/_validation.py\", line 680, in _fit_and_score\n",
      "    estimator.fit(X_train, y_train, **fit_params)\n",
      "  File \"/Users/ahmedabd/miniconda3/envs/my_jupyter_env/lib/python3.9/site-packages/keras/wrappers/scikit_learn.py\", line 236, in fit\n",
      "    return super(KerasClassifier, self).fit(x, y, **kwargs)\n",
      "  File \"/Users/ahmedabd/miniconda3/envs/my_jupyter_env/lib/python3.9/site-packages/keras/wrappers/scikit_learn.py\", line 155, in fit\n",
      "    self.model = self.build_fn(**self.filter_sk_params(self.build_fn))\n",
      "  File \"/var/folders/8z/bf26sjgx09qcs_63cnr3hp880000gn/T/ipykernel_35102/2150697309.py\", line 72, in build_gru_model\n",
      "  File \"/Users/ahmedabd/miniconda3/envs/my_jupyter_env/lib/python3.9/site-packages/tensorflow/python/training/tracking/base.py\", line 587, in _method_wrapper\n",
      "    result = method(self, *args, **kwargs)\n",
      "  File \"/Users/ahmedabd/miniconda3/envs/my_jupyter_env/lib/python3.9/site-packages/keras/utils/traceback_utils.py\", line 67, in error_handler\n",
      "    raise e.with_traceback(filtered_tb) from None\n",
      "  File \"/Users/ahmedabd/miniconda3/envs/my_jupyter_env/lib/python3.9/site-packages/keras/engine/input_spec.py\", line 214, in assert_input_compatibility\n",
      "    raise ValueError(f'Input {input_index} of layer \"{layer_name}\" '\n",
      "ValueError: Input 0 of layer \"gru_19\" is incompatible with the layer: expected ndim=3, found ndim=2. Full shape received: (None, 6)\n",
      "\n",
      "--------------------------------------------------------------------------------\n",
      "4 fits failed with the following error:\n",
      "Traceback (most recent call last):\n",
      "  File \"/Users/ahmedabd/miniconda3/envs/my_jupyter_env/lib/python3.9/site-packages/sklearn/model_selection/_validation.py\", line 680, in _fit_and_score\n",
      "    estimator.fit(X_train, y_train, **fit_params)\n",
      "  File \"/Users/ahmedabd/miniconda3/envs/my_jupyter_env/lib/python3.9/site-packages/keras/wrappers/scikit_learn.py\", line 236, in fit\n",
      "    return super(KerasClassifier, self).fit(x, y, **kwargs)\n",
      "  File \"/Users/ahmedabd/miniconda3/envs/my_jupyter_env/lib/python3.9/site-packages/keras/wrappers/scikit_learn.py\", line 155, in fit\n",
      "    self.model = self.build_fn(**self.filter_sk_params(self.build_fn))\n",
      "  File \"/var/folders/8z/bf26sjgx09qcs_63cnr3hp880000gn/T/ipykernel_35102/2150697309.py\", line 72, in build_gru_model\n",
      "  File \"/Users/ahmedabd/miniconda3/envs/my_jupyter_env/lib/python3.9/site-packages/tensorflow/python/training/tracking/base.py\", line 587, in _method_wrapper\n",
      "    result = method(self, *args, **kwargs)\n",
      "  File \"/Users/ahmedabd/miniconda3/envs/my_jupyter_env/lib/python3.9/site-packages/keras/utils/traceback_utils.py\", line 67, in error_handler\n",
      "    raise e.with_traceback(filtered_tb) from None\n",
      "  File \"/Users/ahmedabd/miniconda3/envs/my_jupyter_env/lib/python3.9/site-packages/keras/engine/input_spec.py\", line 214, in assert_input_compatibility\n",
      "    raise ValueError(f'Input {input_index} of layer \"{layer_name}\" '\n",
      "ValueError: Input 0 of layer \"gru_20\" is incompatible with the layer: expected ndim=3, found ndim=2. Full shape received: (None, 6)\n",
      "\n",
      "--------------------------------------------------------------------------------\n",
      "4 fits failed with the following error:\n",
      "Traceback (most recent call last):\n",
      "  File \"/Users/ahmedabd/miniconda3/envs/my_jupyter_env/lib/python3.9/site-packages/sklearn/model_selection/_validation.py\", line 680, in _fit_and_score\n",
      "    estimator.fit(X_train, y_train, **fit_params)\n",
      "  File \"/Users/ahmedabd/miniconda3/envs/my_jupyter_env/lib/python3.9/site-packages/keras/wrappers/scikit_learn.py\", line 236, in fit\n",
      "    return super(KerasClassifier, self).fit(x, y, **kwargs)\n",
      "  File \"/Users/ahmedabd/miniconda3/envs/my_jupyter_env/lib/python3.9/site-packages/keras/wrappers/scikit_learn.py\", line 155, in fit\n",
      "    self.model = self.build_fn(**self.filter_sk_params(self.build_fn))\n",
      "  File \"/var/folders/8z/bf26sjgx09qcs_63cnr3hp880000gn/T/ipykernel_35102/2150697309.py\", line 72, in build_gru_model\n",
      "  File \"/Users/ahmedabd/miniconda3/envs/my_jupyter_env/lib/python3.9/site-packages/tensorflow/python/training/tracking/base.py\", line 587, in _method_wrapper\n",
      "    result = method(self, *args, **kwargs)\n",
      "  File \"/Users/ahmedabd/miniconda3/envs/my_jupyter_env/lib/python3.9/site-packages/keras/utils/traceback_utils.py\", line 67, in error_handler\n",
      "    raise e.with_traceback(filtered_tb) from None\n",
      "  File \"/Users/ahmedabd/miniconda3/envs/my_jupyter_env/lib/python3.9/site-packages/keras/engine/input_spec.py\", line 214, in assert_input_compatibility\n",
      "    raise ValueError(f'Input {input_index} of layer \"{layer_name}\" '\n",
      "ValueError: Input 0 of layer \"gru_21\" is incompatible with the layer: expected ndim=3, found ndim=2. Full shape received: (None, 6)\n",
      "\n",
      "--------------------------------------------------------------------------------\n",
      "4 fits failed with the following error:\n",
      "Traceback (most recent call last):\n",
      "  File \"/Users/ahmedabd/miniconda3/envs/my_jupyter_env/lib/python3.9/site-packages/sklearn/model_selection/_validation.py\", line 680, in _fit_and_score\n",
      "    estimator.fit(X_train, y_train, **fit_params)\n",
      "  File \"/Users/ahmedabd/miniconda3/envs/my_jupyter_env/lib/python3.9/site-packages/keras/wrappers/scikit_learn.py\", line 236, in fit\n",
      "    return super(KerasClassifier, self).fit(x, y, **kwargs)\n",
      "  File \"/Users/ahmedabd/miniconda3/envs/my_jupyter_env/lib/python3.9/site-packages/keras/wrappers/scikit_learn.py\", line 155, in fit\n",
      "    self.model = self.build_fn(**self.filter_sk_params(self.build_fn))\n",
      "  File \"/var/folders/8z/bf26sjgx09qcs_63cnr3hp880000gn/T/ipykernel_35102/2150697309.py\", line 72, in build_gru_model\n",
      "  File \"/Users/ahmedabd/miniconda3/envs/my_jupyter_env/lib/python3.9/site-packages/tensorflow/python/training/tracking/base.py\", line 587, in _method_wrapper\n",
      "    result = method(self, *args, **kwargs)\n",
      "  File \"/Users/ahmedabd/miniconda3/envs/my_jupyter_env/lib/python3.9/site-packages/keras/utils/traceback_utils.py\", line 67, in error_handler\n",
      "    raise e.with_traceback(filtered_tb) from None\n",
      "  File \"/Users/ahmedabd/miniconda3/envs/my_jupyter_env/lib/python3.9/site-packages/keras/engine/input_spec.py\", line 214, in assert_input_compatibility\n",
      "    raise ValueError(f'Input {input_index} of layer \"{layer_name}\" '\n",
      "ValueError: Input 0 of layer \"gru_22\" is incompatible with the layer: expected ndim=3, found ndim=2. Full shape received: (None, 6)\n",
      "\n",
      "--------------------------------------------------------------------------------\n",
      "4 fits failed with the following error:\n",
      "Traceback (most recent call last):\n",
      "  File \"/Users/ahmedabd/miniconda3/envs/my_jupyter_env/lib/python3.9/site-packages/sklearn/model_selection/_validation.py\", line 680, in _fit_and_score\n",
      "    estimator.fit(X_train, y_train, **fit_params)\n",
      "  File \"/Users/ahmedabd/miniconda3/envs/my_jupyter_env/lib/python3.9/site-packages/keras/wrappers/scikit_learn.py\", line 236, in fit\n",
      "    return super(KerasClassifier, self).fit(x, y, **kwargs)\n",
      "  File \"/Users/ahmedabd/miniconda3/envs/my_jupyter_env/lib/python3.9/site-packages/keras/wrappers/scikit_learn.py\", line 155, in fit\n",
      "    self.model = self.build_fn(**self.filter_sk_params(self.build_fn))\n",
      "  File \"/var/folders/8z/bf26sjgx09qcs_63cnr3hp880000gn/T/ipykernel_35102/2150697309.py\", line 72, in build_gru_model\n",
      "  File \"/Users/ahmedabd/miniconda3/envs/my_jupyter_env/lib/python3.9/site-packages/tensorflow/python/training/tracking/base.py\", line 587, in _method_wrapper\n",
      "    result = method(self, *args, **kwargs)\n",
      "  File \"/Users/ahmedabd/miniconda3/envs/my_jupyter_env/lib/python3.9/site-packages/keras/utils/traceback_utils.py\", line 67, in error_handler\n",
      "    raise e.with_traceback(filtered_tb) from None\n",
      "  File \"/Users/ahmedabd/miniconda3/envs/my_jupyter_env/lib/python3.9/site-packages/keras/engine/input_spec.py\", line 214, in assert_input_compatibility\n",
      "    raise ValueError(f'Input {input_index} of layer \"{layer_name}\" '\n",
      "ValueError: Input 0 of layer \"gru_23\" is incompatible with the layer: expected ndim=3, found ndim=2. Full shape received: (None, 6)\n",
      "\n",
      "--------------------------------------------------------------------------------\n",
      "4 fits failed with the following error:\n",
      "Traceback (most recent call last):\n",
      "  File \"/Users/ahmedabd/miniconda3/envs/my_jupyter_env/lib/python3.9/site-packages/sklearn/model_selection/_validation.py\", line 680, in _fit_and_score\n",
      "    estimator.fit(X_train, y_train, **fit_params)\n",
      "  File \"/Users/ahmedabd/miniconda3/envs/my_jupyter_env/lib/python3.9/site-packages/keras/wrappers/scikit_learn.py\", line 236, in fit\n",
      "    return super(KerasClassifier, self).fit(x, y, **kwargs)\n",
      "  File \"/Users/ahmedabd/miniconda3/envs/my_jupyter_env/lib/python3.9/site-packages/keras/wrappers/scikit_learn.py\", line 155, in fit\n",
      "    self.model = self.build_fn(**self.filter_sk_params(self.build_fn))\n",
      "  File \"/var/folders/8z/bf26sjgx09qcs_63cnr3hp880000gn/T/ipykernel_35102/2150697309.py\", line 72, in build_gru_model\n",
      "  File \"/Users/ahmedabd/miniconda3/envs/my_jupyter_env/lib/python3.9/site-packages/tensorflow/python/training/tracking/base.py\", line 587, in _method_wrapper\n",
      "    result = method(self, *args, **kwargs)\n",
      "  File \"/Users/ahmedabd/miniconda3/envs/my_jupyter_env/lib/python3.9/site-packages/keras/utils/traceback_utils.py\", line 67, in error_handler\n",
      "    raise e.with_traceback(filtered_tb) from None\n",
      "  File \"/Users/ahmedabd/miniconda3/envs/my_jupyter_env/lib/python3.9/site-packages/keras/engine/input_spec.py\", line 214, in assert_input_compatibility\n",
      "    raise ValueError(f'Input {input_index} of layer \"{layer_name}\" '\n",
      "ValueError: Input 0 of layer \"gru_24\" is incompatible with the layer: expected ndim=3, found ndim=2. Full shape received: (None, 6)\n",
      "\n",
      "--------------------------------------------------------------------------------\n",
      "4 fits failed with the following error:\n",
      "Traceback (most recent call last):\n",
      "  File \"/Users/ahmedabd/miniconda3/envs/my_jupyter_env/lib/python3.9/site-packages/sklearn/model_selection/_validation.py\", line 680, in _fit_and_score\n",
      "    estimator.fit(X_train, y_train, **fit_params)\n",
      "  File \"/Users/ahmedabd/miniconda3/envs/my_jupyter_env/lib/python3.9/site-packages/keras/wrappers/scikit_learn.py\", line 236, in fit\n",
      "    return super(KerasClassifier, self).fit(x, y, **kwargs)\n",
      "  File \"/Users/ahmedabd/miniconda3/envs/my_jupyter_env/lib/python3.9/site-packages/keras/wrappers/scikit_learn.py\", line 155, in fit\n",
      "    self.model = self.build_fn(**self.filter_sk_params(self.build_fn))\n",
      "  File \"/var/folders/8z/bf26sjgx09qcs_63cnr3hp880000gn/T/ipykernel_35102/2150697309.py\", line 72, in build_gru_model\n",
      "  File \"/Users/ahmedabd/miniconda3/envs/my_jupyter_env/lib/python3.9/site-packages/tensorflow/python/training/tracking/base.py\", line 587, in _method_wrapper\n",
      "    result = method(self, *args, **kwargs)\n",
      "  File \"/Users/ahmedabd/miniconda3/envs/my_jupyter_env/lib/python3.9/site-packages/keras/utils/traceback_utils.py\", line 67, in error_handler\n",
      "    raise e.with_traceback(filtered_tb) from None\n",
      "  File \"/Users/ahmedabd/miniconda3/envs/my_jupyter_env/lib/python3.9/site-packages/keras/engine/input_spec.py\", line 214, in assert_input_compatibility\n",
      "    raise ValueError(f'Input {input_index} of layer \"{layer_name}\" '\n",
      "ValueError: Input 0 of layer \"gru_25\" is incompatible with the layer: expected ndim=3, found ndim=2. Full shape received: (None, 6)\n",
      "\n",
      "--------------------------------------------------------------------------------\n",
      "4 fits failed with the following error:\n",
      "Traceback (most recent call last):\n",
      "  File \"/Users/ahmedabd/miniconda3/envs/my_jupyter_env/lib/python3.9/site-packages/sklearn/model_selection/_validation.py\", line 680, in _fit_and_score\n",
      "    estimator.fit(X_train, y_train, **fit_params)\n",
      "  File \"/Users/ahmedabd/miniconda3/envs/my_jupyter_env/lib/python3.9/site-packages/keras/wrappers/scikit_learn.py\", line 236, in fit\n",
      "    return super(KerasClassifier, self).fit(x, y, **kwargs)\n",
      "  File \"/Users/ahmedabd/miniconda3/envs/my_jupyter_env/lib/python3.9/site-packages/keras/wrappers/scikit_learn.py\", line 155, in fit\n",
      "    self.model = self.build_fn(**self.filter_sk_params(self.build_fn))\n",
      "  File \"/var/folders/8z/bf26sjgx09qcs_63cnr3hp880000gn/T/ipykernel_35102/2150697309.py\", line 72, in build_gru_model\n",
      "  File \"/Users/ahmedabd/miniconda3/envs/my_jupyter_env/lib/python3.9/site-packages/tensorflow/python/training/tracking/base.py\", line 587, in _method_wrapper\n",
      "    result = method(self, *args, **kwargs)\n",
      "  File \"/Users/ahmedabd/miniconda3/envs/my_jupyter_env/lib/python3.9/site-packages/keras/utils/traceback_utils.py\", line 67, in error_handler\n",
      "    raise e.with_traceback(filtered_tb) from None\n",
      "  File \"/Users/ahmedabd/miniconda3/envs/my_jupyter_env/lib/python3.9/site-packages/keras/engine/input_spec.py\", line 214, in assert_input_compatibility\n",
      "    raise ValueError(f'Input {input_index} of layer \"{layer_name}\" '\n",
      "ValueError: Input 0 of layer \"gru_26\" is incompatible with the layer: expected ndim=3, found ndim=2. Full shape received: (None, 6)\n",
      "\n",
      "  warnings.warn(some_fits_failed_message, FitFailedWarning)\n",
      "/Users/ahmedabd/miniconda3/envs/my_jupyter_env/lib/python3.9/site-packages/sklearn/model_selection/_search.py:969: UserWarning: One or more of the test scores are non-finite: [nan nan nan nan nan nan nan nan nan nan nan nan nan nan nan nan nan nan\n",
      " nan nan nan nan nan nan nan nan nan nan nan nan nan nan nan nan nan nan]\n",
      "  warnings.warn(\n",
      "2024-10-17 12:42:38.743003: I tensorflow/core/platform/cpu_feature_guard.cc:193] This TensorFlow binary is optimized with oneAPI Deep Neural Network Library (oneDNN) to use the following CPU instructions in performance-critical operations:  AVX2 FMA\n",
      "To enable them in other operations, rebuild TensorFlow with the appropriate compiler flags.\n"
     ]
    },
    {
     "ename": "ValueError",
     "evalue": "Input 0 of layer \"gru\" is incompatible with the layer: expected ndim=3, found ndim=2. Full shape received: (None, 6)",
     "output_type": "error",
     "traceback": [
      "\u001b[0;31m---------------------------------------------------------------------------\u001b[0m",
      "\u001b[0;31mValueError\u001b[0m                                Traceback (most recent call last)",
      "Cell \u001b[0;32mIn[1], line 100\u001b[0m\n\u001b[1;32m     97\u001b[0m grid \u001b[38;5;241m=\u001b[39m GridSearchCV(estimator\u001b[38;5;241m=\u001b[39mmodel, param_grid\u001b[38;5;241m=\u001b[39mparam_grid, n_jobs\u001b[38;5;241m=\u001b[39m\u001b[38;5;241m-\u001b[39m\u001b[38;5;241m1\u001b[39m, cv\u001b[38;5;241m=\u001b[39m\u001b[38;5;241m3\u001b[39m, verbose\u001b[38;5;241m=\u001b[39m\u001b[38;5;241m1\u001b[39m)\n\u001b[1;32m     99\u001b[0m \u001b[38;5;66;03m# Fit the grid search\u001b[39;00m\n\u001b[0;32m--> 100\u001b[0m grid_result \u001b[38;5;241m=\u001b[39m \u001b[43mgrid\u001b[49m\u001b[38;5;241;43m.\u001b[39;49m\u001b[43mfit\u001b[49m\u001b[43m(\u001b[49m\u001b[43mX_train\u001b[49m\u001b[43m,\u001b[49m\u001b[43m \u001b[49m\u001b[43mencoded_y_train\u001b[49m\u001b[43m)\u001b[49m\n\u001b[1;32m    102\u001b[0m \u001b[38;5;66;03m# Display the best model and its parameters\u001b[39;00m\n\u001b[1;32m    103\u001b[0m \u001b[38;5;28mprint\u001b[39m(\u001b[38;5;124mf\u001b[39m\u001b[38;5;124m\"\u001b[39m\u001b[38;5;124mBest Accuracy: \u001b[39m\u001b[38;5;132;01m{\u001b[39;00mgrid_result\u001b[38;5;241m.\u001b[39mbest_score_\u001b[38;5;132;01m}\u001b[39;00m\u001b[38;5;124m using \u001b[39m\u001b[38;5;132;01m{\u001b[39;00mgrid_result\u001b[38;5;241m.\u001b[39mbest_params_\u001b[38;5;132;01m}\u001b[39;00m\u001b[38;5;124m\"\u001b[39m)\n",
      "File \u001b[0;32m~/miniconda3/envs/my_jupyter_env/lib/python3.9/site-packages/sklearn/model_selection/_search.py:926\u001b[0m, in \u001b[0;36mBaseSearchCV.fit\u001b[0;34m(self, X, y, groups, **fit_params)\u001b[0m\n\u001b[1;32m    924\u001b[0m refit_start_time \u001b[38;5;241m=\u001b[39m time\u001b[38;5;241m.\u001b[39mtime()\n\u001b[1;32m    925\u001b[0m \u001b[38;5;28;01mif\u001b[39;00m y \u001b[38;5;129;01mis\u001b[39;00m \u001b[38;5;129;01mnot\u001b[39;00m \u001b[38;5;28;01mNone\u001b[39;00m:\n\u001b[0;32m--> 926\u001b[0m     \u001b[38;5;28;43mself\u001b[39;49m\u001b[38;5;241;43m.\u001b[39;49m\u001b[43mbest_estimator_\u001b[49m\u001b[38;5;241;43m.\u001b[39;49m\u001b[43mfit\u001b[49m\u001b[43m(\u001b[49m\u001b[43mX\u001b[49m\u001b[43m,\u001b[49m\u001b[43m \u001b[49m\u001b[43my\u001b[49m\u001b[43m,\u001b[49m\u001b[43m \u001b[49m\u001b[38;5;241;43m*\u001b[39;49m\u001b[38;5;241;43m*\u001b[39;49m\u001b[43mfit_params\u001b[49m\u001b[43m)\u001b[49m\n\u001b[1;32m    927\u001b[0m \u001b[38;5;28;01melse\u001b[39;00m:\n\u001b[1;32m    928\u001b[0m     \u001b[38;5;28mself\u001b[39m\u001b[38;5;241m.\u001b[39mbest_estimator_\u001b[38;5;241m.\u001b[39mfit(X, \u001b[38;5;241m*\u001b[39m\u001b[38;5;241m*\u001b[39mfit_params)\n",
      "File \u001b[0;32m~/miniconda3/envs/my_jupyter_env/lib/python3.9/site-packages/keras/wrappers/scikit_learn.py:236\u001b[0m, in \u001b[0;36mKerasClassifier.fit\u001b[0;34m(self, x, y, **kwargs)\u001b[0m\n\u001b[1;32m    234\u001b[0m   \u001b[38;5;28;01mraise\u001b[39;00m \u001b[38;5;167;01mValueError\u001b[39;00m(\u001b[38;5;124m'\u001b[39m\u001b[38;5;124mInvalid shape for y: \u001b[39m\u001b[38;5;124m'\u001b[39m \u001b[38;5;241m+\u001b[39m \u001b[38;5;28mstr\u001b[39m(y\u001b[38;5;241m.\u001b[39mshape))\n\u001b[1;32m    235\u001b[0m \u001b[38;5;28mself\u001b[39m\u001b[38;5;241m.\u001b[39mn_classes_ \u001b[38;5;241m=\u001b[39m \u001b[38;5;28mlen\u001b[39m(\u001b[38;5;28mself\u001b[39m\u001b[38;5;241m.\u001b[39mclasses_)\n\u001b[0;32m--> 236\u001b[0m \u001b[38;5;28;01mreturn\u001b[39;00m \u001b[38;5;28;43msuper\u001b[39;49m\u001b[43m(\u001b[49m\u001b[43mKerasClassifier\u001b[49m\u001b[43m,\u001b[49m\u001b[43m \u001b[49m\u001b[38;5;28;43mself\u001b[39;49m\u001b[43m)\u001b[49m\u001b[38;5;241;43m.\u001b[39;49m\u001b[43mfit\u001b[49m\u001b[43m(\u001b[49m\u001b[43mx\u001b[49m\u001b[43m,\u001b[49m\u001b[43m \u001b[49m\u001b[43my\u001b[49m\u001b[43m,\u001b[49m\u001b[43m \u001b[49m\u001b[38;5;241;43m*\u001b[39;49m\u001b[38;5;241;43m*\u001b[39;49m\u001b[43mkwargs\u001b[49m\u001b[43m)\u001b[49m\n",
      "File \u001b[0;32m~/miniconda3/envs/my_jupyter_env/lib/python3.9/site-packages/keras/wrappers/scikit_learn.py:155\u001b[0m, in \u001b[0;36mBaseWrapper.fit\u001b[0;34m(self, x, y, **kwargs)\u001b[0m\n\u001b[1;32m    152\u001b[0m   \u001b[38;5;28mself\u001b[39m\u001b[38;5;241m.\u001b[39mmodel \u001b[38;5;241m=\u001b[39m \u001b[38;5;28mself\u001b[39m\u001b[38;5;241m.\u001b[39mbuild_fn(\n\u001b[1;32m    153\u001b[0m       \u001b[38;5;241m*\u001b[39m\u001b[38;5;241m*\u001b[39m\u001b[38;5;28mself\u001b[39m\u001b[38;5;241m.\u001b[39mfilter_sk_params(\u001b[38;5;28mself\u001b[39m\u001b[38;5;241m.\u001b[39mbuild_fn\u001b[38;5;241m.\u001b[39m\u001b[38;5;21m__call__\u001b[39m))\n\u001b[1;32m    154\u001b[0m \u001b[38;5;28;01melse\u001b[39;00m:\n\u001b[0;32m--> 155\u001b[0m   \u001b[38;5;28mself\u001b[39m\u001b[38;5;241m.\u001b[39mmodel \u001b[38;5;241m=\u001b[39m \u001b[38;5;28;43mself\u001b[39;49m\u001b[38;5;241;43m.\u001b[39;49m\u001b[43mbuild_fn\u001b[49m\u001b[43m(\u001b[49m\u001b[38;5;241;43m*\u001b[39;49m\u001b[38;5;241;43m*\u001b[39;49m\u001b[38;5;28;43mself\u001b[39;49m\u001b[38;5;241;43m.\u001b[39;49m\u001b[43mfilter_sk_params\u001b[49m\u001b[43m(\u001b[49m\u001b[38;5;28;43mself\u001b[39;49m\u001b[38;5;241;43m.\u001b[39;49m\u001b[43mbuild_fn\u001b[49m\u001b[43m)\u001b[49m\u001b[43m)\u001b[49m\n\u001b[1;32m    157\u001b[0m \u001b[38;5;28;01mif\u001b[39;00m (losses\u001b[38;5;241m.\u001b[39mis_categorical_crossentropy(\u001b[38;5;28mself\u001b[39m\u001b[38;5;241m.\u001b[39mmodel\u001b[38;5;241m.\u001b[39mloss) \u001b[38;5;129;01mand\u001b[39;00m\n\u001b[1;32m    158\u001b[0m     \u001b[38;5;28mlen\u001b[39m(y\u001b[38;5;241m.\u001b[39mshape) \u001b[38;5;241m!=\u001b[39m \u001b[38;5;241m2\u001b[39m):\n\u001b[1;32m    159\u001b[0m   y \u001b[38;5;241m=\u001b[39m to_categorical(y)\n",
      "Cell \u001b[0;32mIn[1], line 72\u001b[0m, in \u001b[0;36mbuild_gru_model\u001b[0;34m(num_neurons, num_layers, dropout_rate, input_shape)\u001b[0m\n\u001b[1;32m     70\u001b[0m \u001b[38;5;28;01mfor\u001b[39;00m i \u001b[38;5;129;01min\u001b[39;00m \u001b[38;5;28mrange\u001b[39m(num_layers):\n\u001b[1;32m     71\u001b[0m     \u001b[38;5;28;01mif\u001b[39;00m i \u001b[38;5;241m==\u001b[39m \u001b[38;5;241m0\u001b[39m:\n\u001b[0;32m---> 72\u001b[0m         \u001b[43mmodel\u001b[49m\u001b[38;5;241;43m.\u001b[39;49m\u001b[43madd\u001b[49m\u001b[43m(\u001b[49m\u001b[43mGRU\u001b[49m\u001b[43m(\u001b[49m\u001b[43mnum_neurons\u001b[49m\u001b[43m,\u001b[49m\u001b[43m \u001b[49m\u001b[43mreturn_sequences\u001b[49m\u001b[38;5;241;43m=\u001b[39;49m\u001b[43m(\u001b[49m\u001b[43mnum_layers\u001b[49m\u001b[43m \u001b[49m\u001b[38;5;241;43m>\u001b[39;49m\u001b[43m \u001b[49m\u001b[38;5;241;43m1\u001b[39;49m\u001b[43m)\u001b[49m\u001b[43m,\u001b[49m\u001b[43m \u001b[49m\u001b[43minput_shape\u001b[49m\u001b[38;5;241;43m=\u001b[39;49m\u001b[43minput_shape\u001b[49m\u001b[43m)\u001b[49m\u001b[43m)\u001b[49m\n\u001b[1;32m     73\u001b[0m     \u001b[38;5;28;01melse\u001b[39;00m:\n\u001b[1;32m     74\u001b[0m         model\u001b[38;5;241m.\u001b[39madd(GRU(num_neurons, return_sequences\u001b[38;5;241m=\u001b[39m(i \u001b[38;5;241m!=\u001b[39m num_layers \u001b[38;5;241m-\u001b[39m \u001b[38;5;241m1\u001b[39m)))\n",
      "File \u001b[0;32m~/miniconda3/envs/my_jupyter_env/lib/python3.9/site-packages/tensorflow/python/training/tracking/base.py:587\u001b[0m, in \u001b[0;36mno_automatic_dependency_tracking.<locals>._method_wrapper\u001b[0;34m(self, *args, **kwargs)\u001b[0m\n\u001b[1;32m    585\u001b[0m \u001b[38;5;28mself\u001b[39m\u001b[38;5;241m.\u001b[39m_self_setattr_tracking \u001b[38;5;241m=\u001b[39m \u001b[38;5;28;01mFalse\u001b[39;00m  \u001b[38;5;66;03m# pylint: disable=protected-access\u001b[39;00m\n\u001b[1;32m    586\u001b[0m \u001b[38;5;28;01mtry\u001b[39;00m:\n\u001b[0;32m--> 587\u001b[0m   result \u001b[38;5;241m=\u001b[39m \u001b[43mmethod\u001b[49m\u001b[43m(\u001b[49m\u001b[38;5;28;43mself\u001b[39;49m\u001b[43m,\u001b[49m\u001b[43m \u001b[49m\u001b[38;5;241;43m*\u001b[39;49m\u001b[43margs\u001b[49m\u001b[43m,\u001b[49m\u001b[43m \u001b[49m\u001b[38;5;241;43m*\u001b[39;49m\u001b[38;5;241;43m*\u001b[39;49m\u001b[43mkwargs\u001b[49m\u001b[43m)\u001b[49m\n\u001b[1;32m    588\u001b[0m \u001b[38;5;28;01mfinally\u001b[39;00m:\n\u001b[1;32m    589\u001b[0m   \u001b[38;5;28mself\u001b[39m\u001b[38;5;241m.\u001b[39m_self_setattr_tracking \u001b[38;5;241m=\u001b[39m previous_value  \u001b[38;5;66;03m# pylint: disable=protected-access\u001b[39;00m\n",
      "File \u001b[0;32m~/miniconda3/envs/my_jupyter_env/lib/python3.9/site-packages/keras/utils/traceback_utils.py:67\u001b[0m, in \u001b[0;36mfilter_traceback.<locals>.error_handler\u001b[0;34m(*args, **kwargs)\u001b[0m\n\u001b[1;32m     65\u001b[0m \u001b[38;5;28;01mexcept\u001b[39;00m \u001b[38;5;167;01mException\u001b[39;00m \u001b[38;5;28;01mas\u001b[39;00m e:  \u001b[38;5;66;03m# pylint: disable=broad-except\u001b[39;00m\n\u001b[1;32m     66\u001b[0m   filtered_tb \u001b[38;5;241m=\u001b[39m _process_traceback_frames(e\u001b[38;5;241m.\u001b[39m__traceback__)\n\u001b[0;32m---> 67\u001b[0m   \u001b[38;5;28;01mraise\u001b[39;00m e\u001b[38;5;241m.\u001b[39mwith_traceback(filtered_tb) \u001b[38;5;28;01mfrom\u001b[39;00m \u001b[38;5;28;01mNone\u001b[39;00m\n\u001b[1;32m     68\u001b[0m \u001b[38;5;28;01mfinally\u001b[39;00m:\n\u001b[1;32m     69\u001b[0m   \u001b[38;5;28;01mdel\u001b[39;00m filtered_tb\n",
      "File \u001b[0;32m~/miniconda3/envs/my_jupyter_env/lib/python3.9/site-packages/keras/engine/input_spec.py:214\u001b[0m, in \u001b[0;36massert_input_compatibility\u001b[0;34m(input_spec, inputs, layer_name)\u001b[0m\n\u001b[1;32m    212\u001b[0m   ndim \u001b[38;5;241m=\u001b[39m shape\u001b[38;5;241m.\u001b[39mrank\n\u001b[1;32m    213\u001b[0m   \u001b[38;5;28;01mif\u001b[39;00m ndim \u001b[38;5;241m!=\u001b[39m spec\u001b[38;5;241m.\u001b[39mndim:\n\u001b[0;32m--> 214\u001b[0m     \u001b[38;5;28;01mraise\u001b[39;00m \u001b[38;5;167;01mValueError\u001b[39;00m(\u001b[38;5;124mf\u001b[39m\u001b[38;5;124m'\u001b[39m\u001b[38;5;124mInput \u001b[39m\u001b[38;5;132;01m{\u001b[39;00minput_index\u001b[38;5;132;01m}\u001b[39;00m\u001b[38;5;124m of layer \u001b[39m\u001b[38;5;124m\"\u001b[39m\u001b[38;5;132;01m{\u001b[39;00mlayer_name\u001b[38;5;132;01m}\u001b[39;00m\u001b[38;5;124m\"\u001b[39m\u001b[38;5;124m \u001b[39m\u001b[38;5;124m'\u001b[39m\n\u001b[1;32m    215\u001b[0m                      \u001b[38;5;124m'\u001b[39m\u001b[38;5;124mis incompatible with the layer: \u001b[39m\u001b[38;5;124m'\u001b[39m\n\u001b[1;32m    216\u001b[0m                      \u001b[38;5;124mf\u001b[39m\u001b[38;5;124m'\u001b[39m\u001b[38;5;124mexpected ndim=\u001b[39m\u001b[38;5;132;01m{\u001b[39;00mspec\u001b[38;5;241m.\u001b[39mndim\u001b[38;5;132;01m}\u001b[39;00m\u001b[38;5;124m, found ndim=\u001b[39m\u001b[38;5;132;01m{\u001b[39;00mndim\u001b[38;5;132;01m}\u001b[39;00m\u001b[38;5;124m. \u001b[39m\u001b[38;5;124m'\u001b[39m\n\u001b[1;32m    217\u001b[0m                      \u001b[38;5;124mf\u001b[39m\u001b[38;5;124m'\u001b[39m\u001b[38;5;124mFull shape received: \u001b[39m\u001b[38;5;132;01m{\u001b[39;00m\u001b[38;5;28mtuple\u001b[39m(shape)\u001b[38;5;132;01m}\u001b[39;00m\u001b[38;5;124m'\u001b[39m)\n\u001b[1;32m    218\u001b[0m \u001b[38;5;28;01mif\u001b[39;00m spec\u001b[38;5;241m.\u001b[39mmax_ndim \u001b[38;5;129;01mis\u001b[39;00m \u001b[38;5;129;01mnot\u001b[39;00m \u001b[38;5;28;01mNone\u001b[39;00m:\n\u001b[1;32m    219\u001b[0m   ndim \u001b[38;5;241m=\u001b[39m x\u001b[38;5;241m.\u001b[39mshape\u001b[38;5;241m.\u001b[39mrank\n",
      "\u001b[0;31mValueError\u001b[0m: Input 0 of layer \"gru\" is incompatible with the layer: expected ndim=3, found ndim=2. Full shape received: (None, 6)"
     ]
    }
   ],
   "source": [
    "import pandas as pd\n",
    "import numpy as np\n",
    "import os\n",
    "from keras.models import Sequential\n",
    "from keras.layers import GRU, Dense, Dropout\n",
    "from sklearn.preprocessing import StandardScaler, LabelEncoder\n",
    "from sklearn.metrics import confusion_matrix\n",
    "import seaborn as sns\n",
    "import matplotlib.pyplot as plt\n",
    "\n",
    "\n",
    "# Function to clean NaN and infinite values\n",
    "def clean_data(X_train, X_valid, X_test):\n",
    "    X_train.fillna(X_train.mean(), inplace=True)\n",
    "    X_valid.fillna(X_valid.mean(), inplace=True)\n",
    "    X_test.fillna(X_test.mean(), inplace=True)\n",
    "    return X_train, X_valid, X_test\n",
    "\n",
    "\n",
    "# Load data\n",
    "data_train = pd.read_pickle(\"clean_data/train/all_data_train.pkl\")\n",
    "data_valid = pd.read_pickle(\"clean_data/valid/all_data_valid.pkl\")\n",
    "data_test = pd.read_pickle(\"clean_data/test/all_data_test.pkl\")\n",
    "\n",
    "# Split the data into features (X) and target (y)\n",
    "X_train = data_train.drop(\"class\", axis=1)\n",
    "X_valid = data_valid.drop(\"class\", axis=1)\n",
    "X_test = data_test.drop(\"class\", axis=1)\n",
    "\n",
    "y_train = data_train[\"class\"]\n",
    "y_valid = data_valid[\"class\"]\n",
    "y_test = data_test[\"class\"]\n",
    "\n",
    "# Encode the target variable (multi-class encoding)\n",
    "encoder = LabelEncoder()\n",
    "encoder.fit(y_train)\n",
    "encoded_y_train = encoder.transform(y_train)\n",
    "encoded_y_valid = encoder.transform(y_valid)\n",
    "encoded_y_test = encoder.transform(y_test)\n",
    "\n",
    "# Clean the data (replace NaNs and infinities)\n",
    "X_train, X_valid, X_test = clean_data(X_train, X_valid, X_test)\n",
    "\n",
    "# Standardize the data\n",
    "scaler = StandardScaler()\n",
    "X_train = scaler.fit_transform(X_train)\n",
    "X_valid = scaler.transform(X_valid)\n",
    "X_test = scaler.transform(X_test)\n",
    "\n",
    "\n",
    "# Function to build a GRU model with variable layers and neurons\n",
    "def build_gru_model(\n",
    "    num_neurons=32, num_layers=1, dropout_rate=0.2, input_shape=(None,)\n",
    "):\n",
    "    model = Sequential()\n",
    "    for i in range(num_layers):\n",
    "        if i == 0:\n",
    "            model.add(\n",
    "                GRU(\n",
    "                    num_neurons,\n",
    "                    return_sequences=(num_layers > 1),\n",
    "                    input_shape=input_shape,\n",
    "                )\n",
    "            )\n",
    "        else:\n",
    "            model.add(GRU(num_neurons, return_sequences=(i != num_layers - 1)))\n",
    "        model.add(Dropout(dropout_rate))\n",
    "\n",
    "    # Output layer for classification\n",
    "    model.add(Dense(4, activation=\"softmax\"))\n",
    "\n",
    "    # Compile the model\n",
    "    model.compile(\n",
    "        loss=\"sparse_categorical_crossentropy\", optimizer=\"adam\", metrics=[\"accuracy\"]\n",
    "    )\n",
    "    return model\n",
    "\n",
    "\n",
    "# Function to perform manual grid search\n",
    "def manual_grid_search(X_train, y_train, X_valid, y_valid, param_grid):\n",
    "    best_accuracy = 0\n",
    "    best_model = None\n",
    "    best_params = {}\n",
    "\n",
    "    for num_neurons in param_grid[\"num_neurons\"]:\n",
    "        for num_layers in param_grid[\"num_layers\"]:\n",
    "            for dropout_rate in param_grid[\"dropout_rate\"]:\n",
    "                for batch_size in param_grid[\"batch_size\"]:\n",
    "                    print(\n",
    "                        f\"Training model with {num_neurons} neurons, {num_layers} layers, {dropout_rate} dropout, and {batch_size} batch size\"\n",
    "                    )\n",
    "\n",
    "                    # Build and train the model\n",
    "                    input_shape = (\n",
    "                        X_train.shape[1],\n",
    "                    )  # Adjust input shape to match your data\n",
    "                    model = build_gru_model(\n",
    "                        num_neurons, num_layers, dropout_rate, input_shape=input_shape\n",
    "                    )\n",
    "                    model.fit(\n",
    "                        X_train,\n",
    "                        y_train,\n",
    "                        epochs=30,\n",
    "                        batch_size=batch_size,\n",
    "                        validation_data=(X_valid, y_valid),\n",
    "                        verbose=1,\n",
    "                    )\n",
    "\n",
    "                    # Evaluate the model on validation data\n",
    "                    _, accuracy = model.evaluate(X_valid, y_valid)\n",
    "                    print(f\"Validation accuracy: {accuracy}\")\n",
    "\n",
    "                    # Keep track of the best model\n",
    "                    if accuracy > best_accuracy:\n",
    "                        best_accuracy = accuracy\n",
    "                        best_model = model\n",
    "                        best_params = {\n",
    "                            \"num_neurons\": num_neurons,\n",
    "                            \"num_layers\": num_layers,\n",
    "                            \"dropout_rate\": dropout_rate,\n",
    "                            \"batch_size\": batch_size,\n",
    "                        }\n",
    "\n",
    "    return best_model, best_accuracy, best_params\n",
    "\n",
    "\n",
    "# Define the hyperparameter grid manually\n",
    "param_grid = {\n",
    "    \"num_neurons\": [32, 64, 128],\n",
    "    \"num_layers\": [1, 2],\n",
    "    \"dropout_rate\": [0.1, 0.2, 0.3],\n",
    "    \"batch_size\": [32, 64],\n",
    "}\n",
    "\n",
    "# Perform the manual grid search\n",
    "best_model, best_accuracy, best_params = manual_grid_search(\n",
    "    X_train, encoded_y_train, X_valid, encoded_y_valid, param_grid\n",
    ")\n",
    "\n",
    "# Display the best result\n",
    "print(f\"Best validation accuracy: {best_accuracy}\")\n",
    "print(f\"Best parameters: {best_params}\")\n",
    "\n",
    "# Evaluate the best model on the test data\n",
    "X_test_reshaped = X_test.reshape(X_test.shape[0], 1, X_test.shape[1])\n",
    "_, test_accuracy = best_model.evaluate(X_test_reshaped, encoded_y_test)\n",
    "print(f\"Test accuracy: {test_accuracy}\")\n",
    "\n",
    "# Predict on the test data\n",
    "y_pred = np.argmax(best_model.predict(X_test_reshaped), axis=1)\n",
    "\n",
    "# Generate confusion matrix\n",
    "cm = confusion_matrix(encoded_y_test, y_pred)\n",
    "sns.heatmap(cm, annot=True, fmt=\"g\")\n",
    "plt.xlabel(\"Predicted\")\n",
    "plt.ylabel(\"True\")\n",
    "plt.show()\n",
    "\n",
    "\n",
    "# Function to combine pickles with class (existing function)\n",
    "def combine_pickles_with_class(path, class_name):\n",
    "    acc_files = []\n",
    "    gyro_files = []\n",
    "\n",
    "    # List all files in the directory\n",
    "    for file in os.listdir(path):\n",
    "        if file.startswith(class_name) and file.endswith(\"_acc.pkl\"):\n",
    "            acc_files.append(file)\n",
    "        elif file.startswith(class_name) and file.endswith(\"_gyro.pkl\"):\n",
    "            gyro_files.append(file)\n",
    "\n",
    "    combined_data_list = []\n",
    "\n",
    "    # Process and combine acc and gyro files\n",
    "    for i in range(len(acc_files)):\n",
    "        acc_df = pd.read_pickle(os.path.join(path, acc_files[i]))\n",
    "        gyro_df = pd.read_pickle(os.path.join(path, gyro_files[i]))\n",
    "\n",
    "        # Drop the first column if there are 4 columns\n",
    "        if len(acc_df.columns) == 4:\n",
    "            acc_df.drop(acc_df.columns[0], axis=1, inplace=True)\n",
    "            gyro_df.drop(gyro_df.columns[0], axis=1, inplace=True)\n",
    "\n",
    "        acc_df.columns = [\"ax\", \"ay\", \"az\"]\n",
    "        gyro_df.columns = [\"gx\", \"gy\", \"gz\"]\n",
    "\n",
    "        # Combine the acc and gyro dataframes\n",
    "        combined_df = pd.concat([acc_df, gyro_df], axis=1)\n",
    "\n",
    "        combined_data_list.append(combined_df)\n",
    "\n",
    "    # Concatenate all dataframes\n",
    "    final_df = pd.concat(combined_data_list, ignore_index=True)\n",
    "    return final_df\n",
    "\n",
    "\n",
    "# Use the best model to predict on new data\n",
    "new_data = combine_pickles_with_class(\"newdata/\", \"data\")\n",
    "new_data_scaled = scaler.transform(new_data)\n",
    "new_data_reshaped = new_data_scaled.reshape(\n",
    "    new_data_scaled.shape[0], 1, new_data_scaled.shape[1]\n",
    ")\n",
    "new_pred = np.argmax(best_model.predict(new_data_reshaped), axis=1)\n",
    "\n",
    "\n",
    "# Function to plot sensor data with predicted classes\n",
    "def plot_sensor_data(new_data, predicted_classes):\n",
    "    fig, ax = plt.subplots(2, 1, figsize=(12, 10))\n",
    "\n",
    "    # Plot accelerometer data\n",
    "    ax[0].plot(new_data.index, new_data[\"ax\"], label=\"ax\", color=\"b\", linewidth=1.5)\n",
    "    ax[0].plot(new_data.index, new_data[\"ay\"], label=\"ay\", color=\"g\", linewidth=1.5)\n",
    "    ax[0].plot(new_data.index, new_data[\"az\"], label=\"az\", color=\"r\", linewidth=1.5)\n",
    "    ax[0].set_title(\"Accelerometer Data\")\n",
    "    ax[0].legend(loc=\"upper right\")\n",
    "\n",
    "    # Plot gyroscope data\n",
    "    ax[1].plot(new_data.index, new_data[\"gx\"], label=\"gx\", color=\"b\", linewidth=1.5)\n",
    "    ax[1].plot(new_data.index, new_data[\"gy\"], label=\"gy\", color=\"g\", linewidth=1.5)\n",
    "    ax[1].plot(new_data.index, new_data[\"gz\"], label=\"gz\", color=\"r\", linewidth=1.5)\n",
    "    ax[1].set_title(\"Gyroscope Data\")\n",
    "    ax[1].legend(loc=\"upper right\")\n",
    "\n",
    "    # Adding vertical lines at points of class change\n",
    "    class_changes = [\n",
    "        i\n",
    "        for i in range(1, len(predicted_classes))\n",
    "        if predicted_classes[i - 1] != predicted_classes[i]\n",
    "    ]\n",
    "    for change_index in class_changes:\n",
    "        ax[0].axvline(\n",
    "            x=new_data.index[change_index], color=\"k\", linestyle=\"--\", alpha=0.5\n",
    "        )\n",
    "        ax[1].axvline(\n",
    "            x=new_data.index[change_index], color=\"k\", linestyle=\"--\", alpha=0.5\n",
    "        )\n",
    "\n",
    "    plt.tight_layout()\n",
    "    plt.show()\n",
    "\n",
    "\n",
    "# Plot the new data and predicted classes\n",
    "plot_sensor_data(new_data, new_pred)"
   ]
  }
 ],
 "metadata": {
  "kernelspec": {
   "display_name": "my_jupyter_env",
   "language": "python",
   "name": "python3"
  },
  "language_info": {
   "codemirror_mode": {
    "name": "ipython",
    "version": 3
   },
   "file_extension": ".py",
   "mimetype": "text/x-python",
   "name": "python",
   "nbconvert_exporter": "python",
   "pygments_lexer": "ipython3",
   "version": "3.9.19"
  }
 },
 "nbformat": 4,
 "nbformat_minor": 2
}
